Workbook

Sheet Settings
A1: Yorosum Settings
A2: Blue text = input you can change. Yellow fill = replace with your real figure. Black = formula. Green = link to another tab.
A3: Every other tab reads from this one. Change a number here and all prices, margins and totals update.
A5: Exchange rates | B5: Live rate | C5: Manual rate (optional) | D5: Rate used | E5: Note
A6: USD/KRW (KRW per 1 USD) | B6: =GOOGLEFINANCE("CURRENCY:USDKRW") | C6: 1327 | D6: =IF(C6="",B6,C6) | E6: Clear the manual rate to use the live rate.
A7: USD/UZS (UZS per 1 USD) | B7: =GOOGLEFINANCE("CURRENCY:USDUZS") | C7: 12040 | D7: =IF(C7="",B7,C7) | E7: Clear the manual rate to use the live rate.
A8: KRW per 1 UZS | D8: =D6/D7
A10: Product cost | B10: Value | C10: Unit | E10: Note
A11: Cost source | B11: Batches | C11: Batches / Manual | E11: Batches = calculated from the payments on the Batches tab. Manual = use the manual cost below.
A12: Batch to price | B12: B1 | C12: Batch ID | E12: Must match a Batch ID in the summary on the Batches tab.
A13: Units produced in this batch | B13: =VLOOKUP(B12,Batches!$J$4:$M$20,2,FALSE) | C13: units
A14: Factory cost per unit, from batch payments | B14: =VLOOKUP(B12,Batches!$J$4:$M$20,4,FALSE) | C14: KRW
A15: Manual factory cost per unit | C15: KRW | E15: Used only when Cost source = Manual. Use it for what-if scenarios or a quote for the next batch.
A16: Supplier payments include 10% Korean VAT | B16: No | C16: Yes / No | E16: Check the CNS Pharm tax invoice.
A17: Korean purchase VAT can be recovered | B17: Yes | C17: Yes / No | E17: Yes if a VAT-registered Korean company bought the goods.
A18: Factory cost per unit used | B18: =IF(B11="Manual",B15,B14)/IF(AND(B16="Yes",B17="Yes"),1+C49,1) | C18: KRW | E18: Removes Korean VAT when it is included and recoverable.
A20: Air cargo | B20: Value | C20: Unit | E20: Note
A21: Freight source | B21: Estimate | C21: Estimate / Actual / Manual | E21: Estimate = calculated below. Actual = from invoices on the Shipments tab. Manual = the manual figure below.
A22: Freight rate | B22: 10 | C22: USD per kg
A23: Units per carton | B23: 42 | C23: units
A24: Carton weight | B24: 6.5 | C24: kg
A25: Carton length | C25: cm | E25: Airlines charge by volume when it is higher than actual weight. Add carton size to include this.
A26: Carton width | C26: cm
A27: Carton height | C27: cm
A28: Volumetric divisor | B28: 6000 | C28: cm3 per kg | E28: 6,000 is the usual air cargo figure. Confirm with your forwarder.
A29: Fuel and other surcharges | B29: 0 | C29: % of freight | E29: Ask your forwarder for the surcharge on the quote.
A30: Minimum charge per shipment | B30: 0 | C30: USD
A31: Cargo insurance | B31: 0 | C31: % of goods value | E31: Often 0.3% to 0.5%. Enter 0 if not insured.
A32: Units shipped (blank = all units produced) | C32: units
A33: Units shipped | B33: =IF(B32="",B13,B32) | C33: units
A34: Cartons | B34: =ROUNDUP(B33/B23,0) | C34: cartons
A35: Volumetric weight per carton | B35: =B25*B26*B27/B28 | C35: kg
A36: Chargeable weight per carton | B36: =MAX(B24,B35) | C36: kg | E36: The higher of actual and volumetric weight.
A37: Total chargeable weight | B37: =B34*B36 | C37: kg
A38: Freight estimate for the shipment | B38: =MAX(B30,B37*B22*(1+B29)) | C38: USD
A39: Freight per unit, estimate | B39: =IF(B33=0,0,B38*Settings!$D$6/B33) | C39: KRW
A40: Freight per unit, actual | B40: =VLOOKUP(B12,Shipments!$J$4:$N$20,4,FALSE) | C40: KRW | E40: From freight invoices logged on the Shipments tab.
A41: Manual freight per unit | C41: KRW | E41: Used only when Freight source = Manual.
A42: Freight per unit used | B42: =IF(B21="Actual",B40,IF(B21="Manual",B41,B39)) | C42: KRW
A44: Market settings | B44: UZ | C44: KR | E44: Note
...

Sheet Price Calculator
A1: Price Calculator (per unit)
A2: All amounts are KRW per unit unless stated. Inputs live on the Settings tab.
A3: Blue text = input you can change. Yellow fill = replace with your real figure. Black = formula. Green = link to another tab.
A4: Channel | B4: =Settings!B58 | C4: =Settings!C58 | D4: =Settings!D58 | E4: =Settings!E58
A5: Market | B5: =Settings!B59 | C5: =Settings!C59 | D5: =Settings!D59 | E5: =Settings!E59
A6: Market column (helper) | B6: =MATCH(B5,Settings!$B$44:$C$44,0) | C6: =MATCH(C5,Settings!$B$44:$C$44,0) | D6: =MATCH(D5,Settings!$B$44:$C$44,0) | E6: =MATCH(E5,Settings!$B$44:$C$44,0)
A7: Local currency | B7: =INDEX(Settings!$B$46:$C$46,B6) | C7: =INDEX(Settings!$B$46:$C$46,C6) | D7: =INDEX(Settings!$B$46:$C$46,D6) | E7: =INDEX(Settings!$B$46:$C$46,E6)
A8: KRW per 1 unit of local currency | B8: =INDEX(Settings!$B$47:$C$47,B6) | C8: =INDEX(Settings!$B$47:$C$47,C6) | D8: =INDEX(Settings!$B$47:$C$47,D6) | E8: =INDEX(Settings!$B$47:$C$47,E6)
A9: Imported from Korea | B9: =INDEX(Settings!$B$48:$C$48,B6) | C9: =INDEX(Settings!$B$48:$C$48,C6) | D9: =INDEX(Settings!$B$48:$C$48,D6) | E9: =INDEX(Settings!$B$48:$C$48,E6)
A11: Landed cost
A12: Factory cost | B12: =Settings!$B$18 | C12: =Settings!$B$18 | D12: =Settings!$B$18 | E12: =Settings!$B$18
A13: Air freight | B13: =IF(B9="Yes",Settings!$B$42,0) | C13: =IF(C9="Yes",Settings!$B$42,0) | D13: =IF(D9="Yes",Settings!$B$42,0) | E13: =IF(E9="Yes",Settings!$B$42,0)
A14: Cargo insurance | B14: =IF(B9="Yes",B12*Settings!$B$31,0) | C14: =IF(C9="Yes",C12*Settings!$B$31,0) | D14: =IF(D9="Yes",D12*Settings!$B$31,0) | E14: =IF(E9="Yes",E12*Settings!$B$31,0)
A15: Customs value (goods + freight + insurance) | B15: =B12+B13+B14 | C15: =C12+C13+C14 | D15: =D12+D13+D14 | E15: =E12+E13+E14
A16: Customs duty | B16: =IF(B9="Yes",B15*INDEX(Settings!$B$52:$C$52,B6),0) | C16: =IF(C9="Yes",C15*INDEX(Settings!$B$52:$C$52,C6),0) | D16: =IF(D9="Yes",D15*INDEX(Settings!$B$52:$C$52,D6),0) | E16: =IF(E9="Yes",E15*INDEX(Settings!$B$52:$C$52,E6),0)
A17: Import VAT not recovered | B17: =IF(AND(B9="Yes",INDEX(Settings!$B$50:$C$50,B6)="No"),(B15+B16)*INDEX(Settings!$B$49:$C$49,B6),0) | C17: =IF(AND(C9="Yes",INDEX(Settings!$B$50:$C$50,C6)="No"),(C15+C16)*INDEX(Settings!$B$49:$C$49,C6),0) | D17: =IF(AND(D9="Yes",INDEX(Settings!$B$50:$C$50,D6)="No"),(D15+D16)*INDEX(Settings!$B$49:$C$49,D6),0) | E17: =IF(AND(E9="Yes",INDEX(Settings!$B$50:$C$50,E6)="No"),(E15+E16)*INDEX(Settings!$B$49:$C$49,E6),0)
A18: Customs, broker and certification | B18: =IF(INDEX(Settings!$B$56:$C$56,B6)=0,0,INDEX(Settings!$B$53:$C$53,B6)*B8/INDEX(Settings!$B$56:$C$56,B6)) | C18: =IF(INDEX(Settings!$B$56:$C$56,C6)=0,0,INDEX(Settings!$B$53:$C$53,C6)*C8/INDEX(Settings!$B$56:$C$56,C6)) | D18: =IF(INDEX(Settings!$B$56:$C$56,D6)=0,0,INDEX(Settings!$B$53:$C$53,D6)*D8/INDEX(Settings!$B$56:$C$56,D6)) | E18: =IF(INDEX(Settings!$B$56:$C$56,E6)=0,0,INDEX(Settings!$B$53:$C$53,E6)*E8/INDEX(Settings!$B$56:$C$56,E6))
A19: Local delivery and storage | B19: =INDEX(Settings!$B$54:$C$54,B6)*B8 | C19: =INDEX(Settings!$B$54:$C$54,C6)*C8 | D19: =INDEX(Settings!$B$54:$C$54,D6)*D8 | E19: =INDEX(Settings!$B$54:$C$54,E6)*E8
A20: Landed cost | B20: =B15+B16+B17+B18+B19 | C20: =C15+C16+C17+C18+C19 | D20: =D15+D16+D17+D18+D19 | E20: =E15+E16+E17+E18+E19
A22: Sales taxes and channel costs
A23: VAT charged on sales | B23: =IF(INDEX(Settings!$B$50:$C$50,B6)="Yes",INDEX(Settings!$B$49:$C$49,B6),0) | C23: =IF(INDEX(Settings!$B$50:$C$50,C6)="Yes",INDEX(Settings!$B$49:$C$49,C6),0) | D23: =IF(INDEX(Settings!$B$50:$C$50,D6)="Yes",INDEX(Settings!$B$49:$C$49,D6),0) | E23: =IF(INDEX(Settings!$B$50:$C$50,E6)="Yes",INDEX(Settings!$B$49:$C$49,E6),0)
A24: Turnover tax (% of price before VAT) | B24: =IF(INDEX(Settings!$B$50:$C$50,B6)="Yes",0,INDEX(Settings!$B$51:$C$51,B6)) | C24: =IF(INDEX(Settings!$B$50:$C$50,C6)="Yes",0,INDEX(Settings!$B$51:$C$51,C6)) | D24: =IF(INDEX(Settings!$B$50:$C$50,D6)="Yes",0,INDEX(Settings!$B$51:$C$51,D6)) | E24: =IF(INDEX(Settings!$B$50:$C$50,E6)="Yes",0,INDEX(Settings!$B$51:$C$51,E6))
A25: Marketplace and payment fees (% of price incl. VAT) | B25: =Settings!B61+Settings!B62 | C25: =Settings!C61+Settings!C62 | D25: =Settings!D61+Settings!D62 | E25: =Settings!E61+Settings!E62
A26: Shipping and packaging to customer | B26: =Settings!B63*B8 | C26: =Settings!C63*C8 | D26: =Settings!D63*D8 | E26: =Settings!E63*E8
A27: Target margin | B27: =Settings!B60 | C27: =Settings!C60 | D27: =Settings!D60 | E27: =Settings!E60
A29: Price
A30: Price divisor (helper) | B30: =1-B25*(1+B23)-B24-B27 | C30: =1-C25*(1+C23)-C24-C27 | D30: =1-D25*(1+D23)-D24-D27 | E30: =1-E25*(1+E23)-E24-E27
A31: Price from target margin, before VAT | B31: =IF(B30<=0,NA(),(B20+B26)/B30) | C31: =IF(C30<=0,NA(),(C20+C26)/C30) | D31: =IF(D30<=0,NA(),(D20+D26)/D30) | E31: =IF(E30<=0,NA(),(E20+E26)/E30)
A32: Price override, incl. VAT (local currency) | B32: =IF(Settings!B64="","",Settings!B64) | C32: =IF(Settings!C64="","",Settings!C64) | D32: =IF(Settings!D64="","",Settings!D64) | E32: =IF(Settings!E64="","",Settings!E64)
A33: Price used, before VAT | B33: =IF(B32="",B31,B32*B8/(1+B23)) | C33: =IF(C32="",C31,C32*C8/(1+C23)) | D33: =IF(D32="",D31,D32*D8/(1+D23)) | E33: =IF(E32="",E31,E32*E8/(1+E23))
A34: VAT | B34: =B33*B23 | C34: =C33*C23 | D34: =D33*D23 | E34: =E33*E23
A35: Customer price incl. VAT | B35: =B33+B34 | C35: =C33+C34 | D35: =D33+D34 | E35: =E33+E34
A37: Profit
A38: Marketplace and payment fees | B38: =B35*B25 | C38: =C35*C25 | D38: =D35*D25 | E38: =E35*E25
A39: Turnover tax | B39: =B33*B24 | C39: =C33*C24 | D39: =D33*D24 | E39: =E33*E24
A40: Shipping and packaging | B40: =B26 | C40: =C26 | D40: =D26 | E40: =E26
A41: Landed cost | B41: =B20 | C41: =C20 | D41: =D20 | E41: =E20
A42: Profit per unit | B42: =B33-B38-B39-B40-B41 | C42: =C33-C38-C39-C40-C41 | D42: =D33-D38-D39-D40-D41 | E42: =E33-E38-E39-E40-E41
A43: Margin (% of price before VAT) | B43: =IF(B33=0,0,B42/B33) | C43: =IF(C33=0,0,C42/C33) | D43: =IF(D33=0,0,D42/D33) | E43: =IF(E33=0,0,E42/E33)
A44: Markup on landed cost | B44: =IF(B20=0,0,B42/B20) | C44: =IF(C20=0,0,C42/C20) | D44: =IF(D20=0,0,D42/D20) | E44: =IF(E20=0,0,E42/E20)
...

Sheet Dashboard
A1: Yorosum Dashboard
A2: Monthly results come from the Sales and OpEx tabs. Unit economics come from the Price Calculator.
A4: Unit economics (per unit) | B4: ='Price Calculator'!B4 | C4: ='Price Calculator'!C4 | D4: ='Price Calculator'!D4 | E4: ='Price Calculator'!E4
A5: Customer price incl. VAT (local currency) | B5: ='Price Calculator'!B47 | C5: ='Price Calculator'!C47 | D5: ='Price Calculator'!D47 | E5: ='Price Calculator'!E47
A6: Customer price incl. VAT (USD) | B6: ='Price Calculator'!B49 | C6: ='Price Calculator'!C49 | D6: ='Price Calculator'!D49 | E6: ='Price Calculator'!E49
A7: Landed cost (KRW) | B7: ='Price Calculator'!B20 | C7: ='Price Calculator'!C20 | D7: ='Price Calculator'!D20 | E7: ='Price Calculator'!E20
A8: Profit per unit (KRW) | B8: ='Price Calculator'!B42 | C8: ='Price Calculator'!C42 | D8: ='Price Calculator'!D42 | E8: ='Price Calculator'!E42
A9: Margin | B9: ='Price Calculator'!B43 | C9: ='Price Calculator'!C43 | D9: ='Price Calculator'!D43 | E9: ='Price Calculator'!E43
A10: Break-even units | B10: ='Price Calculator'!B61 | C10: ='Price Calculator'!C61 | D10: ='Price Calculator'!D61 | E10: ='Price Calculator'!E61
A12: Sales mix scenario | B12: UZ B2B | C12: UZ B2C | D12: KR B2B | E12: KR B2C | F12: Total
A13: Share of units sold through each channel | B13: 0.5 | C13: 0.3 | D13: 0.1 | E13: 0.1 | F13: =SUM(B13:E13)
A14: Units | B14: =ROUND(Settings!$B$13*B13,0) | C14: =ROUND(Settings!$B$13*C13,0) | D14: =ROUND(Settings!$B$13*D13,0) | E14: =ROUND(Settings!$B$13*E13,0) | F14: =SUM(B14:E14)
A15: Revenue before VAT (KRW) | B15: =B14*'Price Calculator'!B33 | C15: =C14*'Price Calculator'!C33 | D15: =D14*'Price Calculator'!D33 | E15: =E14*'Price Calculator'!E33 | F15: =SUM(B15:E15)
A16: Profit (KRW) | B16: =B14*'Price Calculator'!B42 | C16: =C14*'Price Calculator'!C42 | D16: =D14*'Price Calculator'!D42 | E16: =E14*'Price Calculator'!E42 | F16: =SUM(B16:E16)
A17: Profit (USD) | B17: =B16/Settings!$D$6 | C17: =C16/Settings!$D$6 | D17: =D16/Settings!$D$6 | E17: =E16/Settings!$D$6 | F17: =F16/Settings!$D$6
A19: Stock | B19: Value
A20: Total paid for the batch (KRW) | B20: =VLOOKUP(Settings!$B$12,Batches!$J$4:$M$20,3,FALSE)
A21: Units on hand, all locations | B21: =Inventory!$J$7
A23: Monthly P&L (KRW) | B23: 2026-07 | C23: 2026-08 | D23: 2026-09 | E23: 2026-10 | F23: 2026-11 | G23: 2026-12 | H23: 2027-01 | I23: 2027-02 | J23: 2027-03 | K23: 2027-04 | L23: 2027-05 | M23: 2027-06 | N23: Total
A24: Revenue before VAT | B24: =SUMIFS(Sales!$J:$J,Sales!$P:$P,B$23) | C24: =SUMIFS(Sales!$J:$J,Sales!$P:$P,C$23) | D24: =SUMIFS(Sales!$J:$J,Sales!$P:$P,D$23) | E24: =SUMIFS(Sales!$J:$J,Sales!$P:$P,E$23) | F24: =SUMIFS(Sales!$J:$J,Sales!$P:$P,F$23) | G24: =SUMIFS(Sales!$J:$J,Sales!$P:$P,G$23) | H24: =SUMIFS(Sales!$J:$J,Sales!$P:$P,H$23) | I24: =SUMIFS(Sales!$J:$J,Sales!$P:$P,I$23) | ... M24: =SUMIFS(Sales!$J:$J,Sales!$P:$P,M$23) | N24: =SUM(B24:M24)
A25: Landed cost of goods sold | B25: =SUMIFS(Sales!$M:$M,Sales!$P:$P,B$23) | C25: =SUMIFS(Sales!$M:$M,Sales!$P:$P,C$23) | D25: =SUMIFS(Sales!$M:$M,Sales!$P:$P,D$23) | E25: =SUMIFS(Sales!$M:$M,Sales!$P:$P,E$23) | F25: =SUMIFS(Sales!$M:$M,Sales!$P:$P,F$23) | G25: =SUMIFS(Sales!$M:$M,Sales!$P:$P,G$23) | H25: =SUMIFS(Sales!$M:$M,Sales!$P:$P,H$23) | I25: =SUMIFS(Sales!$M:$M,Sales!$P:$P,I$23) | ... M25: =SUMIFS(Sales!$M:$M,Sales!$P:$P,M$23) | N25: =SUM(B25:M25)
A26: Fees and turnover tax | B26: =SUMIFS(Sales!$K:$K,Sales!$P:$P,B$23) | C26: =SUMIFS(Sales!$K:$K,Sales!$P:$P,C$23) | D26: =SUMIFS(Sales!$K:$K,Sales!$P:$P,D$23) | E26: =SUMIFS(Sales!$K:$K,Sales!$P:$P,E$23) | F26: =SUMIFS(Sales!$K:$K,Sales!$P:$P,F$23) | G26: =SUMIFS(Sales!$K:$K,Sales!$P:$P,G$23) | H26: =SUMIFS(Sales!$K:$K,Sales!$P:$P,H$23) | I26: =SUMIFS(Sales!$K:$K,Sales!$P:$P,I$23) | ... M26: =SUMIFS(Sales!$K:$K,Sales!$P:$P,M$23) | N26: =SUM(B26:M26)
A27: Shipping and packaging | B27: =SUMIFS(Sales!$L:$L,Sales!$P:$P,B$23) | C27: =SUMIFS(Sales!$L:$L,Sales!$P:$P,C$23) | D27: =SUMIFS(Sales!$L:$L,Sales!$P:$P,D$23) | E27: =SUMIFS(Sales!$L:$L,Sales!$P:$P,E$23) | F27: =SUMIFS(Sales!$L:$L,Sales!$P:$P,F$23) | G27: =SUMIFS(Sales!$L:$L,Sales!$P:$P,G$23) | H27: =SUMIFS(Sales!$L:$L,Sales!$P:$P,H$23) | I27: =SUMIFS(Sales!$L:$L,Sales!$P:$P,I$23) | ... M27: =SUMIFS(Sales!$L:$L,Sales!$P:$P,M$23) | N27: =SUM(B27:M27)
A28: Gross profit | B28: =B24-B25-B26-B27 | C28: =C24-C25-C26-C27 | D28: =D24-D25-D26-D27 | E28: =E24-E25-E26-E27 | F28: =F24-F25-F26-F27 | G28: =G24-G25-G26-G27 | H28: =H24-H25-H26-H27 | I28: =I24-I25-I26-I27 | ... M28: =M24-M25-M26-M27 | N28: =SUM(B28:M28)
A29: Operating expenses | B29: =SUMIFS(OpEx!$H:$H,OpEx!$I:$I,B$23) | C29: =SUMIFS(OpEx!$H:$H,OpEx!$I:$I,C$23) | D29: =SUMIFS(OpEx!$H:$H,OpEx!$I:$I,D$23) | E29: =SUMIFS(OpEx!$H:$H,OpEx!$I:$I,E$23) | F29: =SUMIFS(OpEx!$H:$H,OpEx!$I:$I,F$23) | G29: =SUMIFS(OpEx!$H:$H,OpEx!$I:$I,G$23) | H29: =SUMIFS(OpEx!$H:$H,OpEx!$I:$I,H$23) | I29: =SUMIFS(OpEx!$H:$H,OpEx!$I:$I,I$23) | ... M29: =SUMIFS(OpEx!$H:$H,OpEx!$I:$I,M$23) | N29: =SUM(B29:M29)
A30: Net profit | B30: =B28-B29 | C30: =C28-C29 | D30: =D28-D29 | E30: =E28-E29 | F30: =F28-F29 | G30: =G28-G29 | H30: =H28-H29 | I30: =I28-I29 | ... M30: =M28-M29 | N30: =SUM(B30:M30)
A31: Cumulative net profit | B31: =B30 | C31: =B31+C30 | D31: =C31+D30 | E31: =D31+E30 | F31: =E31+F30 | G31: =F31+G30 | H31: =G31+H30 | I31: =H31+I30 | J31: =I31+J30 | ... M31: =L31+M30
A32: Change the month headers to move the 12-month window. They must be text in yyyy-mm form.

Sheet Batches
A1: Production batches
A2: One row per payment. For a new batch, use a new Batch ID and add it to the summary on the right. B1 payments and units: from the original 1st Production Cost tab.
A3: Date | B3: Batch | C3: Paid to | D3: What it covers | E3: Amount | F3: Currency | G3: KRW per unit of currency | H3: Amount (KRW) | J3: Batch | K3: Units produced | L3: Total paid (KRW) | M3: Cost per unit (KRW) | N3: Expiry date
A4: 46254 | B4: B1 | C4: CNS Pharm | D4: Production payment | E4: 9000000 | F4: KRW | G4: =IF(E4="","",IF(F4="KRW",1,IF(F4="USD",Settings!$D$6,IF(F4="UZS",Settings!$D$8,NA())))) | H4: =IF(E4="","",E4*G4) | J4: B1 | K4: 2793 | L4: =SUMIFS($H:$H,$B:$B,J4) | M4: =IF(N(K4)=0,0,L4/K4)
A5: 46307 | B5: B1 | C5: CNS Pharm | D5: Production payment | E5: 10000000 | F5: KRW | G5: =IF(E5="","",IF(F5="KRW",1,IF(F5="USD",Settings!$D$6,IF(F5="UZS",Settings!$D$8,NA())))) | H5: =IF(E5="","",E5*G5) | J5: B2 | L5: =SUMIFS($H:$H,$B:$B,J5) | M5: =IF(N(K5)=0,0,L5/K5)
A6: 46308 | B6: B1 | C6: CNS Pharm | D6: Not labelled in the original sheet | E6: 450640 | F6: KRW | G6: =IF(E6="","",IF(F6="KRW",1,IF(F6="USD",Settings!$D$6,IF(F6="UZS",Settings!$D$8,NA())))) | H6: =IF(E6="","",E6*G6) | J6: B3 | L6: =SUMIFS($H:$H,$B:$B,J6) | M6: =IF(N(K6)=0,0,L6/K6)
A7: 46309 | B7: B1 | C7: CNS Pharm | D7: Not labelled in the original sheet | E7: 564696 | F7: KRW | G7: =IF(E7="","",IF(F7="KRW",1,IF(F7="USD",Settings!$D$6,IF(F7="UZS",Settings!$D$8,NA())))) | H7: =IF(E7="","",E7*G7)
G8: =IF(E8="","",IF(F8="KRW",1,IF(F8="USD",Settings!$D$6,IF(F8="UZS",Settings!$D$8,NA())))) | H8: =IF(E8="","",E8*G8)
G9: =IF(E9="","",IF(F9="KRW",1,IF(F9="USD",Settings!$D$6,IF(F9="UZS",Settings!$D$8,NA())))) | H9: =IF(E9="","",E9*G9)
G10: =IF(E10="","",IF(F10="KRW",1,IF(F10="USD",Settings!$D$6,IF(F10="UZS",Settings!$D$8,NA())))) | H10: =IF(E10="","",E10*G10)
G11: =IF(E11="","",IF(F11="KRW",1,IF(F11="USD",Settings!$D$6,IF(F11="UZS",Settings!$D$8,NA())))) | H11: =IF(E11="","",E11*G11)
G12: =IF(E12="","",IF(F12="KRW",1,IF(F12="USD",Settings!$D$6,IF(F12="UZS",Settings!$D$8,NA())))) | H12: =IF(E12="","",E12*G12)

Sheet Shipments
A1: Shipments and import costs
A2: Log each real invoice. Settings uses the freight total when Freight source = Actual.
A3: Date | B3: Batch | C3: Market | D3: Cost type | E3: Amount | F3: Currency | G3: KRW per unit of currency | H3: Amount (KRW) | J3: Batch | K3: Units shipped | L3: Freight (KRW) | M3: Freight per unit (KRW) | N3: Other import costs (KRW)
G4: =IF(E4="","",IF(F4="KRW",1,IF(F4="USD",Settings!$D$6,IF(F4="UZS",Settings!$D$8,NA())))) | H4: =IF(E4="","",E4*G4) | J4: B1 | K4: =Settings!$B$33 | L4: =SUMIFS($H:$H,$B:$B,J4,$D:$D,"Freight") | M4: =IF(N(K4)=0,0,L4/K4) | N4: =SUMIFS($H:$H,$B:$B,J4)-L4
G5: =IF(E5="","",IF(F5="KRW",1,IF(F5="USD",Settings!$D$6,IF(F5="UZS",Settings!$D$8,NA())))) | H5: =IF(E5="","",E5*G5) | J5: B2 | L5: =SUMIFS($H:$H,$B:$B,J5,$D:$D,"Freight") | M5: =IF(N(K5)=0,0,L5/K5) | N5: =SUMIFS($H:$H,$B:$B,J5)-L5
G6: =IF(E6="","",IF(F6="KRW",1,IF(F6="USD",Settings!$D$6,IF(F6="UZS",Settings!$D$8,NA())))) | H6: =IF(E6="","",E6*G6) | J6: B3 | L6: =SUMIFS($H:$H,$B:$B,J6,$D:$D,"Freight") | M6: =IF(N(K6)=0,0,L6/K6) | N6: =SUMIFS($H:$H,$B:$B,J6)-L6
G7: =IF(E7="","",IF(F7="KRW",1,IF(F7="USD",Settings!$D$6,IF(F7="UZS",Settings!$D$8,NA())))) | H7: =IF(E7="","",E7*G7)
G8: =IF(E8="","",IF(F8="KRW",1,IF(F8="USD",Settings!$D$6,IF(F8="UZS",Settings!$D$8,NA())))) | H8: =IF(E8="","",E8*G8)
G9: =IF(E9="","",IF(F9="KRW",1,IF(F9="USD",Settings!$D$6,IF(F9="UZS",Settings!$D$8,NA())))) | H9: =IF(E9="","",E9*G9)
G10: =IF(E10="","",IF(F10="KRW",1,IF(F10="USD",Settings!$D$6,IF(F10="UZS",Settings!$D$8,NA())))) | H10: =IF(E10="","",E10*G10)
G11: =IF(E11="","",IF(F11="KRW",1,IF(F11="USD",Settings!$D$6,IF(F11="UZS",Settings!$D$8,NA())))) | H11: =IF(E11="","",E11*G11)
G12: =IF(E12="","",IF(F12="KRW",1,IF(F12="USD",Settings!$D$6,IF(F12="UZS",Settings!$D$8,NA())))) | H12: =IF(E12="","",E12*G12)

Sheet Inventory
A1: Inventory movements
A2: Units in are positive, units out are negative.
A3: Date | B3: Batch | C3: Location | D3: Movement | E3: Units | F3: Note | I3: Location | J3: Units on hand
A4: 46309 | B4: B1 | C4: Korea | D4: Received | E4: =Settings!B13 | F4: Date and location assumed. Change to the real ones. | I4: Korea | J4: =SUMIFS($E:$E,$C:$C,I4)
I5: Uzbekistan | J5: =SUMIFS($E:$E,$C:$C,I5)
I6: In transit | J6: =SUMIFS($E:$E,$C:$C,I6)
I7: Total | J7: =SUM(J4:J6)

Sheet Sales
A1: Sales
A2: Enter date, channel, customer, units and price. Profit uses the current landed cost and fees from the Price Calculator.
A3: Date | B3: Channel | C3: Customer | D3: Units | E3: Price per unit incl. VAT (local currency) | F3: Channel # (helper) | G3: KRW per unit of currency | H3: Revenue incl. VAT (KRW) | I3: VAT (KRW) | J3: Revenue before VAT (KRW) | K3: Fees and turnover tax (KRW) | L3: Shipping (KRW) | M3: Landed cost (KRW) | N3: Profit (KRW) | O3: Margin | P3: Month
F4: =IF($B4="","",MATCH($B4,'Price Calculator'!$B$4:$E$4,0)) | G4: =IF($F4="","",INDEX('Price Calculator'!$B$8:$E$8,$F4)) | H4: =IF($F4="","",$D4*$E4*$G4) | I4: =IF($F4="","",$H4-$H4/(1+INDEX('Price Calculator'!$B$23:$E$23,$F4))) | J4: =IF($F4="","",$H4-$I4) | K4: =IF($F4="","",$H4*INDEX('Price Calculator'!$B$25:$E$25,$F4)+$J4*INDEX('Price Calculator'!$B$24:$E$24,$F4)) | L4: =IF($F4="","",$D4*INDEX('Price Calculator'!$B$26:$E$26,$F4)) | M4: =IF($F4="","",$D4*INDEX('Price Calculator'!$B$20:$E$20,$F4)) | N4: =IF($F4="","",$J4-$K4-$L4-$M4) | O4: =IF(N($J4)=0,"",$N4/$J4) | P4: =IF($A4="","",TEXT($A4,"yyyy-mm"))
F5: =IF($B5="","",MATCH($B5,'Price Calculator'!$B$4:$E$4,0)) | G5: =IF($F5="","",INDEX('Price Calculator'!$B$8:$E$8,$F5)) | H5: =IF($F5="","",$D5*$E5*$G5) | I5: =IF($F5="","",$H5-$H5/(1+INDEX('Price Calculator'!$B$23:$E$23,$F5))) | J5: =IF($F5="","",$H5-$I5) | K5: =IF($F5="","",$H5*INDEX('Price Calculator'!$B$25:$E$25,$F5)+$J5*INDEX('Price Calculator'!$B$24:$E$24,$F5)) | L5: =IF($F5="","",$D5*INDEX('Price Calculator'!$B$26:$E$26,$F5)) | M5: =IF($F5="","",$D5*INDEX('Price Calculator'!$B$20:$E$20,$F5)) | N5: =IF($F5="","",$J5-$K5-$L5-$M5) | O5: =IF(N($J5)=0,"",$N5/$J5) | P5: =IF($A5="","",TEXT($A5,"yyyy-mm"))
F6: =IF($B6="","",MATCH($B6,'Price Calculator'!$B$4:$E$4,0)) | G6: =IF($F6="","",INDEX('Price Calculator'!$B$8:$E$8,$F6)) | H6: =IF($F6="","",$D6*$E6*$G6) | I6: =IF($F6="","",$H6-$H6/(1+INDEX('Price Calculator'!$B$23:$E$23,$F6))) | J6: =IF($F6="","",$H6-$I6) | K6: =IF($F6="","",$H6*INDEX('Price Calculator'!$B$25:$E$25,$F6)+$J6*INDEX('Price Calculator'!$B$24:$E$24,$F6)) | L6: =IF($F6="","",$D6*INDEX('Price Calculator'!$B$26:$E$26,$F6)) | M6: =IF($F6="","",$D6*INDEX('Price Calculator'!$B$20:$E$20,$F6)) | N6: =IF($F6="","",$J6-$K6-$L6-$M6) | O6: =IF(N($J6)=0,"",$N6/$J6) | P6: =IF($A6="","",TEXT($A6,"yyyy-mm"))
F7: =IF($B7="","",MATCH($B7,'Price Calculator'!$B$4:$E$4,0)) | G7: =IF($F7="","",INDEX('Price Calculator'!$B$8:$E$8,$F7)) | H7: =IF($F7="","",$D7*$E7*$G7) | I7: =IF($F7="","",$H7-$H7/(1+INDEX('Price Calculator'!$B$23:$E$23,$F7))) | J7: =IF($F7="","",$H7-$I7) | K7: =IF($F7="","",$H7*INDEX('Price Calculator'!$B$25:$E$25,$F7)+$J7*INDEX('Price Calculator'!$B$24:$E$24,$F7)) | L7: =IF($F7="","",$D7*INDEX('Price Calculator'!$B$26:$E$26,$F7)) | M7: =IF($F7="","",$D7*INDEX('Price Calculator'!$B$20:$E$20,$F7)) | N7: =IF($F7="","",$J7-$K7-$L7-$M7) | O7: =IF(N($J7)=0,"",$N7/$J7) | P7: =IF($A7="","",TEXT($A7,"yyyy-mm"))
F8: =IF($B8="","",MATCH($B8,'Price Calculator'!$B$4:$E$4,0)) | G8: =IF($F8="","",INDEX('Price Calculator'!$B$8:$E$8,$F8)) | H8: =IF($F8="","",$D8*$E8*$G8) | I8: =IF($F8="","",$H8-$H8/(1+INDEX('Price Calculator'!$B$23:$E$23,$F8))) | J8: =IF($F8="","",$H8-$I8) | K8: =IF($F8="","",$H8*INDEX('Price Calculator'!$B$25:$E$25,$F8)+$J8*INDEX('Price Calculator'!$B$24:$E$24,$F8)) | L8: =IF($F8="","",$D8*INDEX('Price Calculator'!$B$26:$E$26,$F8)) | M8: =IF($F8="","",$D8*INDEX('Price Calculator'!$B$20:$E$20,$F8)) | N8: =IF($F8="","",$J8-$K8-$L8-$M8) | O8: =IF(N($J8)=0,"",$N8/$J8) | P8: =IF($A8="","",TEXT($A8,"yyyy-mm"))
F9: =IF($B9="","",MATCH($B9,'Price Calculator'!$B$4:$E$4,0)) | G9: =IF($F9="","",INDEX('Price Calculator'!$B$8:$E$8,$F9)) | H9: =IF($F9="","",$D9*$E9*$G9) | I9: =IF($F9="","",$H9-$H9/(1+INDEX('Price Calculator'!$B$23:$E$23,$F9))) | J9: =IF($F9="","",$H9-$I9) | K9: =IF($F9="","",$H9*INDEX('Price Calculator'!$B$25:$E$25,$F9)+$J9*INDEX('Price Calculator'!$B$24:$E$24,$F9)) | L9: =IF($F9="","",$D9*INDEX('Price Calculator'!$B$26:$E$26,$F9)) | M9: =IF($F9="","",$D9*INDEX('Price Calculator'!$B$20:$E$20,$F9)) | N9: =IF($F9="","",$J9-$K9-$L9-$M9) | O9: =IF(N($J9)=0,"",$N9/$J9) | P9: =IF($A9="","",TEXT($A9,"yyyy-mm"))
F10: =IF($B10="","",MATCH($B10,'Price Calculator'!$B$4:$E$4,0)) | G10: =IF($F10="","",INDEX('Price Calculator'!$B$8:$E$8,$F10)) | H10: =IF($F10="","",$D10*$E10*$G10) | I10: =IF($F10="","",$H10-$H10/(1+INDEX('Price Calculator'!$B$23:$E$23,$F10))) | J10: =IF($F10="","",$H10-$I10) | K10: =IF($F10="","",$H10*INDEX('Price Calculator'!$B$25:$E$25,$F10)+$J10*INDEX('Price Calculator'!$B$24:$E$24,$F10)) | L10: =IF($F10="","",$D10*INDEX('Price Calculator'!$B$26:$E$26,$F10)) | M10: =IF($F10="","",$D10*INDEX('Price Calculator'!$B$20:$E$20,$F10)) | N10: =IF($F10="","",$J10-$K10-$L10-$M10) | O10: =IF(N($J10)=0,"",$N10/$J10) | P10: =IF($A10="","",TEXT($A10,"yyyy-mm"))
F11: =IF($B11="","",MATCH($B11,'Price Calculator'!$B$4:$E$4,0)) | G11: =IF($F11="","",INDEX('Price Calculator'!$B$8:$E$8,$F11)) | H11: =IF($F11="","",$D11*$E11*$G11) | I11: =IF($F11="","",$H11-$H11/(1+INDEX('Price Calculator'!$B$23:$E$23,$F11))) | J11: =IF($F11="","",$H11-$I11) | K11: =IF($F11="","",$H11*INDEX('Price Calculator'!$B$25:$E$25,$F11)+$J11*INDEX('Price Calculator'!$B$24:$E$24,$F11)) | L11: =IF($F11="","",$D11*INDEX('Price Calculator'!$B$26:$E$26,$F11)) | M11: =IF($F11="","",$D11*INDEX('Price Calculator'!$B$20:$E$20,$F11)) | N11: =IF($F11="","",$J11-$K11-$L11-$M11) | O11: =IF(N($J11)=0,"",$N11/$J11) | P11: =IF($A11="","",TEXT($A11,"yyyy-mm"))
F12: =IF($B12="","",MATCH($B12,'Price Calculator'!$B$4:$E$4,0)) | G12: =IF($F12="","",INDEX('Price Calculator'!$B$8:$E$8,$F12)) | H12: =IF($F12="","",$D12*$E12*$G12) | I12: =IF($F12="","",$H12-$H12/(1+INDEX('Price Calculator'!$B$23:$E$23,$F12))) | J12: =IF($F12="","",$H12-$I12) | K12: =IF($F12="","",$H12*INDEX('Price Calculator'!$B$25:$E$25,$F12)+$J12*INDEX('Price Calculator'!$B$24:$E$24,$F12)) | L12: =IF($F12="","",$D12*INDEX('Price Calculator'!$B$26:$E$26,$F12)) | M12: =IF($F12="","",$D12*INDEX('Price Calculator'!$B$20:$E$20,$F12)) | N12: =IF($F12="","",$J12-$K12-$L12-$M12) | O12: =IF(N($J12)=0,"",$N12/$J12) | P12: =IF($A12="","",TEXT($A12,"yyyy-mm"))
F13: =IF($B13="","",MATCH($B13,'Price Calculator'!$B$4:$E$4,0)) | G13: =IF($F13="","",INDEX('Price Calculator'!$B$8:$E$8,$F13)) | H13: =IF($F13="","",$D13*$E13*$G13) | I13: =IF($F13="","",$H13-$H13/(1+INDEX('Price Calculator'!$B$23:$E$23,$F13))) | J13: =IF($F13="","",$H13-$I13) | K13: =IF($F13="","",$H13*INDEX('Price Calculator'!$B$25:$E$25,$F13)+$J13*INDEX('Price Calculator'!$B$24:$E$24,$F13)) | L13: =IF($F13="","",$D13*INDEX('Price Calculator'!$B$26:$E$26,$F13)) | M13: =IF($F13="","",$D13*INDEX('Price Calculator'!$B$20:$E$20,$F13)) | N13: =IF($F13="","",$J13-$K13-$L13-$M13) | O13: =IF(N($J13)=0,"",$N13/$J13) | P13: =IF($A13="","",TEXT($A13,"yyyy-mm"))
A15: Rows 4 to 13 have formulas. To add more rows, copy the last row down.

Sheet OpEx
A1: Operating expenses
A2: One row per expense. First two rows are from the original sheet: currency was not stated (KRW assumed) and the second date said 2027 (changed to 2026).
A3: Date | B3: Category | C3: Vendor | D3: Description | E3: Amount | F3: Currency | G3: KRW per unit of currency | H3: Amount (KRW) | I3: Month
A4: 46230 | B4: AI tools | E4: 35884 | F4: KRW | G4: =IF(E4="","",IF(F4="KRW",1,IF(F4="USD",Settings!$D$6,IF(F4="UZS",Settings!$D$8,NA())))) | H4: =IF(E4="","",E4*G4) | I4: =IF(A4="","",TEXT(A4,"yyyy-mm"))
A5: 46231 | B5: AI tools | E5: 35838 | F5: KRW | G5: =IF(E5="","",IF(F5="KRW",1,IF(F5="USD",Settings!$D$6,IF(F5="UZS",Settings!$D$8,NA())))) | H5: =IF(E5="","",E5*G5) | I5: =IF(A5="","",TEXT(A5,"yyyy-mm"))
G6: =IF(E6="","",IF(F6="KRW",1,IF(F6="USD",Settings!$D$6,IF(F6="UZS",Settings!$D$8,NA())))) | H6: =IF(E6="","",E6*G6) | I6: =IF(A6="","",TEXT(A6,"yyyy-mm"))
G7: =IF(E7="","",IF(F7="KRW",1,IF(F7="USD",Settings!$D$6,IF(F7="UZS",Settings!$D$8,NA())))) | H7: =IF(E7="","",E7*G7) | I7: =IF(A7="","",TEXT(A7,"yyyy-mm"))
G8: =IF(E8="","",IF(F8="KRW",1,IF(F8="USD",Settings!$D$6,IF(F8="UZS",Settings!$D$8,NA())))) | H8: =IF(E8="","",E8*G8) | I8: =IF(A8="","",TEXT(A8,"yyyy-mm"))
G9: =IF(E9="","",IF(F9="KRW",1,IF(F9="USD",Settings!$D$6,IF(F9="UZS",Settings!$D$8,NA())))) | H9: =IF(E9="","",E9*G9) | I9: =IF(A9="","",TEXT(A9,"yyyy-mm"))
G10: =IF(E10="","",IF(F10="KRW",1,IF(F10="USD",Settings!$D$6,IF(F10="UZS",Settings!$D$8,NA())))) | H10: =IF(E10="","",E10*G10) | I10: =IF(A10="","",TEXT(A10,"yyyy-mm"))
G11: =IF(E11="","",IF(F11="KRW",1,IF(F11="USD",Settings!$D$6,IF(F11="UZS",Settings!$D$8,NA())))) | H11: =IF(E11="","",E11*G11) | I11: =IF(A11="","",TEXT(A11,"yyyy-mm"))
G12: =IF(E12="","",IF(F12="KRW",1,IF(F12="USD",Settings!$D$6,IF(F12="UZS",Settings!$D$8,NA())))) | H12: =IF(E12="","",E12*G12) | I12: =IF(A12="","",TEXT(A12,"yyyy-mm"))
